Loading model with FP32...
Done with 0.10s
Traceback (most recent call last):
  File "/pscratch/sd/g/gzquse/quanta_env/lib/python3.12/site-packages/huggingface_hub/utils/_errors.py", line 304, in hf_raise_for_status
    response.raise_for_status()
  File "/pscratch/sd/g/gzquse/quanta_env/lib/python3.12/site-packages/requests/models.py", line 1024, in raise_for_status
    raise HTTPError(http_error_msg, response=self)
requests.exceptions.HTTPError: 401 Client Error: Unauthorized for url: https://huggingface.co/meta-llama/Llama-2-7b-hf/resolve/main/config.json
The above exception was the direct cause of the following exception:
Traceback (most recent call last):
  File "/pscratch/sd/g/gzquse/quanta_env/lib/python3.12/site-packages/transformers/utils/hub.py", line 402, in cached_file
    resolved_file = hf_hub_download(
                    ^^^^^^^^^^^^^^^^
  File "/pscratch/sd/g/gzquse/quanta_env/lib/python3.12/site-packages/huggingface_hub/utils/_deprecation.py", line 101, in inner_f
    return f(*args, **kwargs)
           ^^^^^^^^^^^^^^^^^^
  File "/pscratch/sd/g/gzquse/quanta_env/lib/python3.12/site-packages/huggingface_hub/utils/_validators.py", line 114, in _inner_fn
    return fn(*args, **kwargs)
           ^^^^^^^^^^^^^^^^^^^
  File "/pscratch/sd/g/gzquse/quanta_env/lib/python3.12/site-packages/huggingface_hub/file_download.py", line 1240, in hf_hub_download
    return _hf_hub_download_to_cache_dir(
           ^^^^^^^^^^^^^^^^^^^^^^^^^^^^^^
  File "/pscratch/sd/g/gzquse/quanta_env/lib/python3.12/site-packages/huggingface_hub/file_download.py", line 1347, in _hf_hub_download_to_cache_dir
    _raise_on_head_call_error(head_call_error, force_download, local_files_only)
  File "/pscratch/sd/g/gzquse/quanta_env/lib/python3.12/site-packages/huggingface_hub/file_download.py", line 1854, in _raise_on_head_call_error
    raise head_call_error
  File "/pscratch/sd/g/gzquse/quanta_env/lib/python3.12/site-packages/huggingface_hub/file_download.py", line 1751, in _get_metadata_or_catch_error
    metadata = get_hf_file_metadata(
               ^^^^^^^^^^^^^^^^^^^^^
  File "/pscratch/sd/g/gzquse/quanta_env/lib/python3.12/site-packages/huggingface_hub/utils/_validators.py", line 114, in _inner_fn
    return fn(*args, **kwargs)
           ^^^^^^^^^^^^^^^^^^^
  File "/pscratch/sd/g/gzquse/quanta_env/lib/python3.12/site-packages/huggingface_hub/file_download.py", line 1673, in get_hf_file_metadata
    r = _request_wrapper(
        ^^^^^^^^^^^^^^^^^
  File "/pscratch/sd/g/gzquse/quanta_env/lib/python3.12/site-packages/huggingface_hub/file_download.py", line 376, in _request_wrapper
    response = _request_wrapper(
               ^^^^^^^^^^^^^^^^^
  File "/pscratch/sd/g/gzquse/quanta_env/lib/python3.12/site-packages/huggingface_hub/file_download.py", line 400, in _request_wrapper
    hf_raise_for_status(response)
  File "/pscratch/sd/g/gzquse/quanta_env/lib/python3.12/site-packages/huggingface_hub/utils/_errors.py", line 321, in hf_raise_for_status
    raise GatedRepoError(message, response) from e
huggingface_hub.utils._errors.GatedRepoError: 401 Client Error. (Request ID: Root=1-66bbd226-22ac6e0177bf12ce3cb3e708;0a0f3a21-a439-4e8e-84c1-2b06020cdaf3)
Cannot access gated repo for url https://huggingface.co/meta-llama/Llama-2-7b-hf/resolve/main/config.json.
Access to model meta-llama/Llama-2-7b-hf is restricted. You must be authenticated to access it.
The above exception was the direct cause of the following exception:
Traceback (most recent call last):
  File "/pscratch/sd/g/gzquse/quanta/run/run.py", line 485, in <module>
    main()
  File "/pscratch/sd/g/gzquse/quanta/run/run.py", line 457, in main
    framework = Framework(args, task)
                ^^^^^^^^^^^^^^^^^^^^^
  File "/pscratch/sd/g/gzquse/quanta/run/run.py", line 120, in __init__
    self.model, self.tokenizer = self.load_model()
                                 ^^^^^^^^^^^^^^^^^
  File "/pscratch/sd/g/gzquse/quanta/run/run.py", line 124, in load_model
    config = AutoConfig.from_pretrained(self.args.model_name)
             ^^^^^^^^^^^^^^^^^^^^^^^^^^^^^^^^^^^^^^^^^^^^^^^^
  File "/pscratch/sd/g/gzquse/quanta_env/lib/python3.12/site-packages/transformers/models/auto/configuration_auto.py", line 976, in from_pretrained
    config_dict, unused_kwargs = PretrainedConfig.get_config_dict(pretrained_model_name_or_path, **kwargs)
                                 ^^^^^^^^^^^^^^^^^^^^^^^^^^^^^^^^^^^^^^^^^^^^^^^^^^^^^^^^^^^^^^^^^^^^^^^^^
  File "/pscratch/sd/g/gzquse/quanta_env/lib/python3.12/site-packages/transformers/configuration_utils.py", line 632, in get_config_dict
    config_dict, kwargs = cls._get_config_dict(pretrained_model_name_or_path, **kwargs)
                          ^^^^^^^^^^^^^^^^^^^^^^^^^^^^^^^^^^^^^^^^^^^^^^^^^^^^^^^^^^^^^
  File "/pscratch/sd/g/gzquse/quanta_env/lib/python3.12/site-packages/transformers/configuration_utils.py", line 689, in _get_config_dict
    resolved_config_file = cached_file(
                           ^^^^^^^^^^^^
  File "/pscratch/sd/g/gzquse/quanta_env/lib/python3.12/site-packages/transformers/utils/hub.py", line 420, in cached_file
    raise EnvironmentError(
OSError: You are trying to access a gated repo.
Make sure to have access to it at https://huggingface.co/meta-llama/Llama-2-7b-hf.
401 Client Error. (Request ID: Root=1-66bbd226-22ac6e0177bf12ce3cb3e708;0a0f3a21-a439-4e8e-84c1-2b06020cdaf3)
Cannot access gated repo for url https://huggingface.co/meta-llama/Llama-2-7b-hf/resolve/main/config.json.
Access to model meta-llama/Llama-2-7b-hf is restricted. You must be authenticated to access it.